<?xml version="1.0"?>
<robot xmlns:xacro="http://www.ros.org/wiki/xacro">

    <!-- Define robot constants -->
    <xacro:property name="base_width" value="0.31"/>
    <xacro:property name="base_length" value="0.42"/>
    <xacro:property name="base_height" value="0.18"/>

    <xacro:property name="wheel_radius" value="0.10"/>
    <xacro:property name="wheel_width" value="0.04"/>
    <xacro:property name="wheel_ygap" value="0.025"/>
    <xacro:property name="wheel_zoff" value="0.05"/>
    <xacro:property name="wheel_xoff" value="0.12"/>

    <xacro:property name="caster_xoff" value="0.14"/>

    <!-- Colors-->
    <material name="black">
        <color rgba="0.0 0.0 0.0 1.0"/>
    </material>

    <material name="dark">
        <color rgba="0.3 0.3 0.3 1.0"/>
    </material>

    <material name="light_black">
        <color rgba="0.4 0.4 0.4 1.0"/>
    </material>

    <material name="blue">
        <color rgba="0.0 0.0 0.8 1.0"/>
    </material>

    <material name="green">
        <color rgba="0.0 0.8 0.0 1.0"/>
    </material>

    <material name="grey">
        <color rgba="0.5 0.5 0.5 1.0"/>
    </material>

    <material name="orange">
        <color rgba="1.0 0.4235 0.0392 1.0"/>
    </material>

    <material name="brown">
        <color rgba="0.8706 0.8118 0.7647 1.0"/>
    </material>

    <material name="red">
        <color rgba="0.8 0.0 0.0 1.0"/>
    </material>

    <material name="white">
        <color rgba="1.0 1.0 1.0 1.0"/>
    </material>

    <!--macros-->
      <!-- Define intertial property macros  -->
    <xacro:macro name="box_inertia" params="mass x y z *origin">
        <inertial>
            <xacro:insert_block name="origin"/>
            <mass value="${mass}" />
            <inertia ixx="${(1/12) * mass * (y*y+z*z)}" ixy="0.0" ixz="0.0"
                    iyy="${(1/12) * mass * (x*x+z*z)}" iyz="0.0"
                    izz="${(1/12) * mass * (x*x+y*y)}" />
        </inertial>
    </xacro:macro>

    <xacro:macro name="cylinder_inertia" params="m r h">
        <inertial>
        <origin xyz="0 0 0" rpy="${pi/2} 0 0" />
        <mass value="${m}"/>
        <inertia ixx="${(m/12) * (3*r*r + h*h)}" ixy = "0" ixz = "0" iyy="${(m/12) * (3*r*r + h*h)}" iyz = "0" izz="${(m/2) * (r*r)}"/>
        </inertial>
    </xacro:macro>

    <xacro:macro name="sphere_inertia" params="m r">
        <inertial>
        <mass value="${m}"/>
        <inertia ixx="${(2/5) * m * (r*r)}" ixy="0.0" ixz="0.0" iyy="${(2/5) * m * (r*r)}" iyz="0.0" izz="${(2/5) * m * (r*r)}"/>
        </inertial>
    </xacro:macro>


    <!-- Box -->
    <xacro:macro name = "insert_box" params = "name mass color *origin">
        <link name="${name}">
            <visual>
                <geometry>
                    <box size="${base_length} ${base_width} ${base_height}"/>
                </geometry>
                <material name="${color}"/>
            </visual>
            <xacro:box_inertia mass="${mass}" x="${base_length}" y="${base_width}" z="${base_height}">
                <xacro:insert_block name="origin"/>
            </xacro:box_inertia>        
            <collision>
                <xacro:insert_block name="origin"/>
                <geometry>
                    <box size="${base_length} ${base_width} ${base_height}"/>
                </geometry>
            </collision>
        </link>
    </xacro:macro>

    <!-- Cylinder-->
    <xacro:macro name = "insert_cylinder" params = "name mass length radius color *origin">
        <link name="${name}">
            <inertial>
                <xacro:insert_block name = "origin" />
                <mass value="${mass}"/>
                <inertia ixx="${(1/12) * mass * (3*radius*radius + length*length)}" ixy="0.0" ixz="0.0"
                    iyy="${(1/12) * mass * (3*radius*radius + length*length)}" iyz="0.0"
                    izz="${(1/2) * mass * (radius*radius)}" />
            </inertial>
            <visual>
                <xacro:insert_block name = "origin" />
                <material name="${color}"/>
                <geometry>
                    <cylinder radius="${radius}" length="${length}"/>
                </geometry>
            </visual>
            <collision>
                <xacro:insert_block name = "origin" />
                <geometry>
                    <cylinder radius="${radius}" length="${length}"/>
                </geometry>
            </collision>            
        </link>
    </xacro:macro>

    <!-- wheels -->
    <xacro:macro name="wheel" params="prefix x_reflect y_reflect color">
        <link name="${prefix}_link">
            <visual>
                <origin xyz="0 0 0" rpy="${pi/2} 0 0"/>
                <geometry>
                    <cylinder radius="${wheel_radius}" length="${wheel_width}"/>
                </geometry>
                <material name="${color}"/>
            </visual>
            <collision>
                <origin xyz="0 0 0" rpy="${pi/2} 0 0"/>
                <geometry>
                    <cylinder radius="${wheel_radius}" length="${wheel_width}"/>
                </geometry>
            </collision>

      <xacro:cylinder_inertia m="0.5" r="${wheel_radius}" h="${wheel_width}"/>
        </link>

        <joint name="${prefix}_joint" type="continuous">
        <parent link="base_link"/>
        <child link="${prefix}_link"/>
        <origin xyz="${x_reflect*wheel_xoff} ${y_reflect*(base_width/2+wheel_ygap)} ${-wheel_zoff}" rpy="0 0 0"/>
        <axis xyz="0 1 0"/>
        </joint>
    </xacro:macro>
    
</robot>
